Workbook

Sheet SETUP
B2: SETUP
B6: IF YOU DON'T KNOW HOW TO USE THE SPREADSHEET
B7: OPTION 1 : Read me - Instruction file
B8: Savings Tracker Instructions
B17: DEFINE YOUR CURRENCY SYMBOL
B18: $

Sheet SAVINGS TRACKER
B2: SAVINGS TRACKER | G2: GLOBAL GOAL AMOUNT | L2: TOTAL SAVED | Q2: TOTAL LEFT TO SAVE | V2: GLOBAL PROGRESSION | AA2: GLOBAL MONTHLY GOAL
G4: =CONCATENATE(SETUP!B18,TEXT(G6,"#,##0")) -> $0 | L4: =CONCATENATE(SETUP!B18,TEXT(L6,"#,##0")) -> $0 | Q4: =CONCATENATE(SETUP!B18,TEXT(Q6,"#,##0")) -> $0 | V4: =IF(G6=0,"",L6/G6) | AA4: =CONCATENATE(SETUP!B18,TEXT(AA6,"#,##0")) -> $0
G6: =J24 -> 0 | L6: =R24 -> 0 | Q6: =T24 -> 0 | AA6: =M24 -> 0
B7: CONTRIBUTION TRACKER | G7: FUNDS OVERVIEW
B8: DATE | C8: GOAL NAME | D8: AMOUNT | G8: GOAL NAME | I8: GOAL AMOUNT | L8: MONTHLY GOAL | N8: START | Q8: SAVED | S8: LEFT | V8: PROG | AA8: MONTHS LEFT | AC8: ESTIMATE DATE
D9: =IF(E9="","",SETUP!$B$18) | F9: 1 | I9: =IF(J9="","",SETUP!$B$18) | L9: =IF(M9="","",SETUP!$B$18) | N9: =IF(O9="","",SETUP!$B$18) | Q9: =IF(R9="","",SETUP!$B$18) | R9: =IF(G9="","",O9+SUMIF($C$9:$C$81,G9,$E$9:$E$81)) | S9: =IF(T9="","",SETUP!$B$18) | T9: =IF(G9="","",J9-R9) | V9: =IF(G9="","",R9/J9) | X9: =IFERROR(__xludf.DUMMYFUNCTION("if(V9="""","""",SPARKLINE(V9,{""charttype"",""bar"";""max"",1;""color1"",""#cae6ed""}))"),"") | AA9: =IF(G9="","",ROUND(T9/M9,0)) | AC9: =IF(G9="","",TODAY()+AA9*30) | AE9: =IF(V9="",0,V9) -> 0
D10: =IF(E10="","",SETUP!$B$18) | F10: 2 | I10: =IF(J10="","",SETUP!$B$18) | L10: =IF(M10="","",SETUP!$B$18) | N10: =IF(O10="","",SETUP!$B$18) | Q10: =IF(R10="","",SETUP!$B$18) | R10: =IF(G10="","",O10+SUMIF($C$9:$C$81,G10,$E$9:$E$81)) | S10: =IF(T10="","",SETUP!$B$18) | T10: =IF(G10="","",J10-R10) | V10: =IF(G10="","",R10/J10) | X10: =IFERROR(__xludf.DUMMYFUNCTION("if(V10="""","""",SPARKLINE(V10,{""charttype"",""bar"";""max"",1;""color1"",""#cae6ed""}))"),"") | AA10: =IF(G10="","",ROUND(T10/M10,0)) | AC10: =IF(G10="","",TODAY()+AA10*30) | AE10: =IF(V10="",0,V10) -> 0
D11: =IF(E11="","",SETUP!$B$18) | F11: 3 | I11: =IF(J11="","",SETUP!$B$18) | L11: =IF(M11="","",SETUP!$B$18) | N11: =IF(O11="","",SETUP!$B$18) | Q11: =IF(R11="","",SETUP!$B$18) | R11: =IF(G11="","",O11+SUMIF($C$9:$C$81,G11,$E$9:$E$81)) | S11: =IF(T11="","",SETUP!$B$18) | T11: =IF(G11="","",J11-R11) | V11: =IF(G11="","",R11/J11) | X11: =IFERROR(__xludf.DUMMYFUNCTION("if(V11="""","""",SPARKLINE(V11,{""charttype"",""bar"";""max"",1;""color1"",""#cae6ed""}))"),"") | AA11: =IF(G11="","",ROUND(T11/M11,0)) | AC11: =IF(G11="","",TODAY()+AA11*30) | AE11: =IF(V11="",0,V11) -> 0
D12: =IF(E12="","",SETUP!$B$18) | F12: 4 | I12: =IF(J12="","",SETUP!$B$18) | L12: =IF(M12="","",SETUP!$B$18) | N12: =IF(O12="","",SETUP!$B$18) | Q12: =IF(R12="","",SETUP!$B$18) | R12: =IF(G12="","",O12+SUMIF($C$9:$C$81,G12,$E$9:$E$81)) | S12: =IF(T12="","",SETUP!$B$18) | T12: =IF(G12="","",J12-R12) | V12: =IF(G12="","",R12/J12) | X12: =IFERROR(__xludf.DUMMYFUNCTION("if(V12="""","""",SPARKLINE(V12,{""charttype"",""bar"";""max"",1;""color1"",""#cae6ed""}))"),"") | AA12: =IF(G12="","",ROUND(T12/M12,0)) | AC12: =IF(G12="","",TODAY()+AA12*30) | AE12: =IF(V12="",0,V12) -> 0
D13: =IF(E13="","",SETUP!$B$18) | F13: 5 | I13: =IF(J13="","",SETUP!$B$18) | L13: =IF(M13="","",SETUP!$B$18) | N13: =IF(O13="","",SETUP!$B$18) | Q13: =IF(R13="","",SETUP!$B$18) | R13: =IF(G13="","",O13+SUMIF($C$9:$C$81,G13,$E$9:$E$81)) | S13: =IF(T13="","",SETUP!$B$18) | T13: =IF(G13="","",J13-R13) | V13: =IF(G13="","",R13/J13) | X13: =IFERROR(__xludf.DUMMYFUNCTION("if(V13="""","""",SPARKLINE(V13,{""charttype"",""bar"";""max"",1;""color1"",""#cae6ed""}))"),"") | AA13: =IF(G13="","",ROUND(T13/M13,0)) | AC13: =IF(G13="","",TODAY()+AA13*30) | AE13: =IF(V13="",0,V13) -> 0
D14: =IF(E14="","",SETUP!$B$18) | F14: 6 | I14: =IF(J14="","",SETUP!$B$18) | L14: =IF(M14="","",SETUP!$B$18) | N14: =IF(O14="","",SETUP!$B$18) | Q14: =IF(R14="","",SETUP!$B$18) | R14: =IF(G14="","",O14+SUMIF($C$9:$C$81,G14,$E$9:$E$81)) | S14: =IF(T14="","",SETUP!$B$18) | T14: =IF(G14="","",J14-R14) | V14: =IF(G14="","",R14/J14) | X14: =IFERROR(__xludf.DUMMYFUNCTION("if(V14="""","""",SPARKLINE(V14,{""charttype"",""bar"";""max"",1;""color1"",""#cae6ed""}))"),"") | AA14: =IF(G14="","",ROUND(T14/M14,0)) | AC14: =IF(G14="","",TODAY()+AA14*30) | AE14: =IF(V14="",0,V14) -> 0
D15: =IF(E15="","",SETUP!$B$18) | F15: 7 | I15: =IF(J15="","",SETUP!$B$18) | L15: =IF(M15="","",SETUP!$B$18) | N15: =IF(O15="","",SETUP!$B$18) | Q15: =IF(R15="","",SETUP!$B$18) | R15: =IF(G15="","",O15+SUMIF($C$9:$C$81,G15,$E$9:$E$81)) | S15: =IF(T15="","",SETUP!$B$18) | T15: =IF(G15="","",J15-R15) | V15: =IF(G15="","",R15/J15) | X15: =IFERROR(__xludf.DUMMYFUNCTION("if(V15="""","""",SPARKLINE(V15,{""charttype"",""bar"";""max"",1;""color1"",""#cae6ed""}))"),"") | AA15: =IF(G15="","",ROUND(T15/M15,0)) | AC15: =IF(G15="","",TODAY()+AA15*30) | AE15: =IF(V15="",0,V15) -> 0
D16: =IF(E16="","",SETUP!$B$18) | F16: 8 | I16: =IF(J16="","",SETUP!$B$18) | L16: =IF(M16="","",SETUP!$B$18) | N16: =IF(O16="","",SETUP!$B$18) | Q16: =IF(R16="","",SETUP!$B$18) | R16: =IF(G16="","",O16+SUMIF($C$9:$C$81,G16,$E$9:$E$81)) | S16: =IF(T16="","",SETUP!$B$18) | T16: =IF(G16="","",J16-R16) | V16: =IF(G16="","",R16/J16) | X16: =IFERROR(__xludf.DUMMYFUNCTION("if(V16="""","""",SPARKLINE(V16,{""charttype"",""bar"";""max"",1;""color1"",""#cae6ed""}))"),"") | AA16: =IF(G16="","",ROUND(T16/M16,0)) | AC16: =IF(G16="","",TODAY()+AA16*30) | AE16: =IF(V16="",0,V16) -> 0
D17: =IF(E17="","",SETUP!$B$18) | F17: 9 | I17: =IF(J17="","",SETUP!$B$18) | L17: =IF(M17="","",SETUP!$B$18) | N17: =IF(O17="","",SETUP!$B$18) | Q17: =IF(R17="","",SETUP!$B$18) | R17: =IF(G17="","",O17+SUMIF($C$9:$C$81,G17,$E$9:$E$81)) | S17: =IF(T17="","",SETUP!$B$18) | T17: =IF(G17="","",J17-R17) | V17: =IF(G17="","",R17/J17) | X17: =IFERROR(__xludf.DUMMYFUNCTION("if(V17="""","""",SPARKLINE(V17,{""charttype"",""bar"";""max"",1;""color1"",""#cae6ed""}))"),"") | AA17: =IF(G17="","",ROUND(T17/M17,0)) | AC17: =IF(G17="","",TODAY()+AA17*30) | AE17: =IF(V17="",0,V17) -> 0
D18: =IF(E18="","",SETUP!$B$18) | F18: 10 | I18: =IF(J18="","",SETUP!$B$18) | L18: =IF(M18="","",SETUP!$B$18) | N18: =IF(O18="","",SETUP!$B$18) | Q18: =IF(R18="","",SETUP!$B$18) | R18: =IF(G18="","",O18+SUMIF($C$9:$C$81,G18,$E$9:$E$81)) | S18: =IF(T18="","",SETUP!$B$18) | T18: =IF(G18="","",J18-R18) | V18: =IF(G18="","",R18/J18) | X18: =IFERROR(__xludf.DUMMYFUNCTION("if(V18="""","""",SPARKLINE(V18,{""charttype"",""bar"";""max"",1;""color1"",""#cae6ed""}))"),"") | AA18: =IF(G18="","",ROUND(T18/M18,0)) | AC18: =IF(G18="","",TODAY()+AA18*30) | AE18: =IF(V18="",0,V18) -> 0
D19: =IF(E19="","",SETUP!$B$18) | F19: 11 | I19: =IF(J19="","",SETUP!$B$18) | L19: =IF(M19="","",SETUP!$B$18) | N19: =IF(O19="","",SETUP!$B$18) | Q19: =IF(R19="","",SETUP!$B$18) | R19: =IF(G19="","",O19+SUMIF($C$9:$C$81,G19,$E$9:$E$81)) | S19: =IF(T19="","",SETUP!$B$18) | T19: =IF(G19="","",J19-R19) | V19: =IF(G19="","",R19/J19) | X19: =IFERROR(__xludf.DUMMYFUNCTION("if(V19="""","""",SPARKLINE(V19,{""charttype"",""bar"";""max"",1;""color1"",""#cae6ed""}))"),"") | AA19: =IF(G19="","",ROUND(T19/M19,0)) | AC19: =IF(G19="","",TODAY()+AA19*30) | AE19: =IF(V19="",0,V19) -> 0
D20: =IF(E20="","",SETUP!$B$18) | F20: 12 | I20: =IF(J20="","",SETUP!$B$18) | L20: =IF(M20="","",SETUP!$B$18) | N20: =IF(O20="","",SETUP!$B$18) | Q20: =IF(R20="","",SETUP!$B$18) | R20: =IF(G20="","",O20+SUMIF($C$9:$C$81,G20,$E$9:$E$81)) | S20: =IF(T20="","",SETUP!$B$18) | T20: =IF(G20="","",J20-R20) | V20: =IF(G20="","",R20/J20) | X20: =IFERROR(__xludf.DUMMYFUNCTION("if(V20="""","""",SPARKLINE(V20,{""charttype"",""bar"";""max"",1;""color1"",""#cae6ed""}))"),"") | AA20: =IF(G20="","",ROUND(T20/M20,0)) | AC20: =IF(G20="","",TODAY()+AA20*30) | AE20: =IF(V20="",0,V20) -> 0
D21: =IF(E21="","",SETUP!$B$18) | F21: 13 | I21: =IF(J21="","",SETUP!$B$18) | L21: =IF(M21="","",SETUP!$B$18) | N21: =IF(O21="","",SETUP!$B$18) | Q21: =IF(R21="","",SETUP!$B$18) | R21: =IF(G21="","",O21+SUMIF($C$9:$C$81,G21,$E$9:$E$81)) | S21: =IF(T21="","",SETUP!$B$18) | T21: =IF(G21="","",J21-R21) | V21: =IF(G21="","",R21/J21) | X21: =IFERROR(__xludf.DUMMYFUNCTION("if(V21="""","""",SPARKLINE(V21,{""charttype"",""bar"";""max"",1;""color1"",""#cae6ed""}))"),"") | AA21: =IF(G21="","",ROUND(T21/M21,0)) | AC21: =IF(G21="","",TODAY()+AA21*30) | AE21: =IF(V21="",0,V21) -> 0
D22: =IF(E22="","",SETUP!$B$18) | F22: 14 | I22: =IF(J22="","",SETUP!$B$18) | L22: =IF(M22="","",SETUP!$B$18) | N22: =IF(O22="","",SETUP!$B$18) | Q22: =IF(R22="","",SETUP!$B$18) | R22: =IF(G22="","",O22+SUMIF($C$9:$C$81,G22,$E$9:$E$81)) | S22: =IF(T22="","",SETUP!$B$18) | T22: =IF(G22="","",J22-R22) | V22: =IF(G22="","",R22/J22) | X22: =IFERROR(__xludf.DUMMYFUNCTION("if(V22="""","""",SPARKLINE(V22,{""charttype"",""bar"";""max"",1;""color1"",""#cae6ed""}))"),"") | AA22: =IF(G22="","",ROUND(T22/M22,0)) | AC22: =IF(G22="","",TODAY()+AA22*30) | AE22: =IF(V22="",0,V22) -> 0
D23: =IF(E23="","",SETUP!$B$18) | F23: 15 | I23: =IF(J23="","",SETUP!$B$18) | L23: =IF(M23="","",SETUP!$B$18) | N23: =IF(O23="","",SETUP!$B$18) | Q23: =IF(R23="","",SETUP!$B$18) | R23: =IF(G23="","",O23+SUMIF($C$9:$C$81,G23,$E$9:$E$81)) | S23: =IF(T23="","",SETUP!$B$18) | T23: =IF(G23="","",J23-R23) | V23: =IF(G23="","",R23/J23) | X23: =IFERROR(__xludf.DUMMYFUNCTION("if(V23="""","""",SPARKLINE(V23,{""charttype"",""bar"";""max"",1;""color1"",""#cae6ed""}))"),"") | AA23: =IF(G23="","",ROUND(T23/M23,0)) | AC23: =IF(G23="","",TODAY()+AA23*30) | AE23: =IF(V23="",0,V23) -> 0
D24: =IF(E24="","",SETUP!$B$18) | G24: TOTAL | I24: =SETUP!$B$18 -> $ | J24: =SUM(J9:K23) -> 0 | L24: =SETUP!$B$18 -> $ | M24: =SUM(M9:M23) -> 0 | N24: =SETUP!$B$18 -> $ | O24: =SUM(O9:O23) -> 0 | Q24: =SETUP!$B$18 -> $ | R24: =SUM(R9:R23) -> 0 | S24: =SETUP!$B$18 -> $ | T24: =SUM(T9:T23) -> 0 | V24: =V4
D25: =IF(E25="","",SETUP!$B$18)
D26: =IF(E26="","",SETUP!$B$18) | G26: =UPPER(G9) | L26: =UPPER(G10) | Q26: =UPPER(G11) | V26: =UPPER(G12) | AA26: =UPPER(G13)
D27: =IF(E27="","",SETUP!$B$18)
D28: =IF(E28="","",SETUP!$B$18) | G28: =IF(J39=0,"",J40/J39) | L28: =IF(O39=0,"",O40/O39) | Q28: =IF(T39=0,"",T40/T39) | V28: =IF(Y39=0,"",Y40/Y39) | AA28: =IF(AD39=0,"",AD40/AD39)
D29: =IF(E29="","",SETUP!$B$18)
D30: =IF(E30="","",SETUP!$B$18)
D31: =IF(E31="","",SETUP!$B$18)
D32: =IF(E32="","",SETUP!$B$18)
D33: =IF(E33="","",SETUP!$B$18)
D34: =IF(E34="","",SETUP!$B$18)
D35: =IF(E35="","",SETUP!$B$18)
D36: =IF(E36="","",SETUP!$B$18)
D37: =IF(E37="","",SETUP!$B$18)
D38: =IF(E38="","",SETUP!$B$18)
D39: =IF(E39="","",SETUP!$B$18) | G39: GOAL AMOUNT | I39: =SETUP!$B$18 -> $ | J39: =IF($J9="",0,$J9) -> 0 | L39: GOAL AMOUNT | N39: =SETUP!$B$18 -> $ | O39: =IF($J10="",0,$J10) -> 0 | Q39: GOAL AMOUNT | S39: =SETUP!$B$18 -> $ | T39: =IF($J11="",0,$J11) -> 0 | V39: GOAL AMOUNT | X39: =SETUP!$B$18 -> $ | Y39: =IF($J12="",0,$J12) -> 0 | AA39: GOAL AMOUNT | AC39: =SETUP!$B$18 -> $ | AD39: =IF($J13="",0,$J13) -> 0
D40: =IF(E40="","",SETUP!$B$18) | G40: SAVED | I40: =SETUP!$B$18 -> $ | J40: =IF($R9="",0,$R9) -> 0 | L40: SAVED | N40: =SETUP!$B$18 -> $ | O40: =IF($R10="",0,$R10) -> 0 | Q40: SAVED | S40: =SETUP!$B$18 -> $ | T40: =IF($R11="",0,$R11) -> 0 | V40: SAVED | X40: =SETUP!$B$18 -> $ | Y40: =IF($R12="",0,$R12) -> 0 | AA40: SAVED | AC40: =SETUP!$B$18 -> $ | AD40: =IF($R13="",0,$R13) -> 0
D41: =IF(E41="","",SETUP!$B$18) | G41: LEFT | I41: =SETUP!$B$18 -> $ | J41: =IF($T9="",0,$T9) -> 0 | L41: LEFT | N41: =SETUP!$B$18 -> $ | O41: =IF($T10="",0,$T10) -> 0 | Q41: LEFT | S41: =SETUP!$B$18 -> $ | T41: =IF($T11="",0,$T11) -> 0 | V41: LEFT | X41: =SETUP!$B$18 -> $ | Y41: =IF($T12="",0,$T12) -> 0 | AA41: LEFT | AC41: =SETUP!$B$18 -> $ | AD41: =IF($T13="",0,$T13) -> 0
D42: =IF(E42="","",SETUP!$B$18) | G42: MONTH LEFT | I42: =$AA9 | L42: MONTH LEFT | N42: =$AA10 | Q42: MONTH LEFT | S42: =$AA11 | V42: MONTH LEFT | X42: =$AA12 | AA42: MONTH LEFT | AC42: =$AA13
D43: =IF(E43="","",SETUP!$B$18) | G43: ESTIMATE DATE | I43: =$AC9 | L43: ESTIMATE DATE | N43: =$AC10 | Q43: ESTIMATE DATE | S43: =$AC11 | V43: ESTIMATE DATE | X43: =$AC12 | AA43: ESTIMATE DATE | AC43: =$AC13
...
